Workbook

Sheet Projects
A1: Team | B1: Top_cell | C1: gds_file | D1: width | E1: height | F1: Size Check | G1: Export | H1: Status | I1: Slot Type | J1: Pin Count | K1: power | L1: ground | M1: analog-ESD | N1: analog+ESD | O1: input_cmos | P1: input_schmitt | Q1: bidirectional | R1: bidirectional_24ma | S1: unmatched | T1: errors
A2: A01 | B2: chip_top | C2: chip_top.gds | D2: 1110 | E2: 550 | F2: =IFERROR(and(vlookup(D2,Blocks!E$2:E$12,1,0),vlookup(E2,Blocks!F$2:F$12,1,0)),false) -> TRUE | G2: =ifna(if(vlookup(A2,Export!B:B,1,0)<>"","OK"),"") -> OK | H2: =vlookup(A2,Status!A:C,3,0) | I2: =IFERROR(__xludf.DUMMYFUNCTION("IF(or(D2="""",J2=0,L2=""0:""),"""",IFNA(INDEX(FILTER(Blocks!$A$2:$A1006, Blocks!$E$2:$E1006>=D2, Blocks!$F$2:$F1006>=E2, Blocks!$D$2:$D1006>=J2),1),""X""))"),"BH") -> BH | J2: =left(K2,find(":",K2)-1)+left(L2,find(":",L2)-1)+left(M2,find(":",M2)-1)+left(N2,find(":",N2)-1)+left(O2,find(":",O2)-1)+left(P2,find(":",P2)-1)+left(Q2,find(":",Q2)-1)+left(R2,find(":",R2)-1) -> 12 | K2: 2:VDDA VDDD | L2: 2:VSSA VSSD | M2: 7:IBIAS ISS VTUNE CP_OUT Q_N I_N Q_P | N2: 0: | O2: 1:REF_IN | P2: 0: | Q2: 0: | R2: 0: | S2: 1:I_P
A3: A02 | B3: A02_A | C3: A02_A.gds | D3: 1110 | E3: 1110 | F3: =IFERROR(and(vlookup(D3,Blocks!E$2:E$12,1,0),vlookup(E3,Blocks!F$2:F$12,1,0)),false) -> TRUE | G3: =ifna(if(vlookup(A3,Export!B:B,1,0)<>"","OK"),"") -> OK | H3: =vlookup(A3,Status!A:C,3,0) | I3: =IFERROR(__xludf.DUMMYFUNCTION("IF(or(D3="""",J3=0,L3=""0:""),"""",IFNA(INDEX(FILTER(Blocks!$A$2:$A1006, Blocks!$E$2:$E1006>=D3, Blocks!$F$2:$F1006>=E3, Blocks!$D$2:$D1006>=J3),1),""X""))"),"X") -> X | J3: =left(K3,find(":",K3)-1)+left(L3,find(":",L3)-1)+left(M3,find(":",M3)-1)+left(N3,find(":",N3)-1)+left(O3,find(":",O3)-1)+left(P3,find(":",P3)-1)+left(Q3,find(":",Q3)-1)+left(R3,find(":",R3)-1) -> 146 | K3: 1:VDD | L3: 1:VSS | M3: 0: | N3: 0: | O3: 19:clk data_IN[7] data_IN[5] data_IN[6] data_IN[4] data_IN[0] data_IN[1] data_IN[2] data_IN[3] addr[0] addr[1] addr[2] addr[3] irq_IN re debug_state_IN[0] debug_state_IN[2] debug_state_IN[1] we | P3: 1:rst_n | Q3: 124:clk_PU clk_PD data_CS[7] data_SL[7] data_IE[7] data_OE[7] data_PU[7] data_PD[7] data_OUT[7] data_PDRV0[7] data_PDRV1[7] data_CS[5] data_SL[5] data_IE[5] data_OE[5] data_PU[5] data_PD[5] data_OUT[5] data_PDRV0[5] data_PDRV1[5] data_CS[6] data_SL[6] data_IE[6] data_OE[6] data_PU[6] data_PD[6] data_OUT[6] data_PDRV0[6] data_PDRV1[6] data_CS[4] data_SL[4] data_IE[4] data_OE[4] data_PU[4] data_PD[4] data_OUT[4] data_PDRV0[4] data_PDRV1[4] data_CS[0] data_SL[0] data_IE[0] data_OE[0] data_PU[0] data_PD[0] data_OUT[0] data_PDRV0[0] data_PDRV1[0] data_CS[1] data_SL[1] data_IE[1] data_OE[1] data_PU[1] data_PD[1] data_OUT[1] data_PDRV0[1] data_PDRV1[1] data_CS[2] data_SL[2] data_IE[2] data_OE[2] data_PU[2] data_PD[2] data_OUT[2] data_PDRV0[2] data_PDRV1[2] data_CS[3] data_SL[3] data_IE[3] data_OE[3] data_PU[3] data_PD[3] data_OUT[3] data_PDRV0[3] data_PDRV1[3] addr_PU[0] addr_PD[0] addr_PU[1] addr_PD[1] addr_PU[2] addr_PD[2] addr_PU[3] addr_PD[3] irq_CS irq_SL irq_IE irq_OE irq_PU irq_PD irq_OUT irq_PDRV0 irq_PDRV1 re_PU re_PD debug_state_CS[0] debug_state_SL[0] debug_state_IE[0] debug_state_OE[0] debug_state_PU[0] debug_state_PD[0] debug_state_OUT[0] debug_state_PDRV0[0] debug_state_PDRV1[0] debug_state_CS[2] debug_state_SL[2] debug_state_IE[2] debug_state_OE[2] debug_state_PU[2] debug_state_PD[2] debug_state_OUT[2] debug_state_PDRV0[2] debug_state_PDRV1[2] debug_state_CS[1] debug_state_SL[1] debug_state_IE[1] debug_state_OE[1] debug_state_PU[1] debug_state_PD[1] debug_state_OUT[1] debug_state_PDRV0[1] debug_state_PDRV1[1] we_PU we_PD rst_n_PU rst_n_PD | R3: 0: | S3: 0:
A4: A06 | B4: A06_BH_top_wrapper | C4: A06_BH_top_wrapper.gds | D4: 1110 | E4: 550 | F4: =IFERROR(and(vlookup(D4,Blocks!E$2:E$12,1,0),vlookup(E4,Blocks!F$2:F$12,1,0)),false) -> TRUE | G4: =ifna(if(vlookup(A4,Export!B:B,1,0)<>"","OK"),"") -> OK | H4: =vlookup(A4,Status!A:C,3,0) | I4: =IFERROR(__xludf.DUMMYFUNCTION("IF(or(D4="""",J4=0,L4=""0:""),"""",IFNA(INDEX(FILTER(Blocks!$A$2:$A1006, Blocks!$E$2:$E1006>=D4, Blocks!$F$2:$F1006>=E4, Blocks!$D$2:$D1006>=J4),1),""X""))"),"BH") -> BH | J4: =left(K4,find(":",K4)-1)+left(L4,find(":",L4)-1)+left(M4,find(":",M4)-1)+left(N4,find(":",N4)-1)+left(O4,find(":",O4)-1)+left(P4,find(":",P4)-1)+left(Q4,find(":",Q4)-1)+left(R4,find(":",R4)-1) -> 16 | K4: 1:VDD | L4: 1:VSS | M4: 0: | N4: 0: | O4: 8:clk spi_in0 spi_in1 spi_in2 spi_in3 load_row_or_col input_ready output_valid | P4: 1:rst_n | Q4: 5:spi_out0 spi_out1 spi_out2 spi_out3 output_ready | R4: 0: | S4: 1774:clknet_0_clk clknet_3_0_0_clk clknet_3_1_0_clk clknet_3_2_0_clk clknet_3_3_0_clk clknet_3_4_0_clk clknet_3_5_0_clk clknet_3_6_0_clk clknet_3_7_0_clk clknet_4_0__leaf_clk clknet_4_10__leaf_clk clknet_4_11__leaf_clk clknet_4_12__leaf_clk clknet_4_13__leaf_clk clknet_4_14__leaf_clk clknet_4_15__leaf_clk clknet_4_1__leaf_clk clknet_4_2__leaf_clk clknet_4_3__leaf_clk clknet_4_4__leaf_clk clknet_4_5__leaf_clk clknet_4_6__leaf_clk clknet_4_7__leaf_clk clknet_4_8__leaf_clk clknet_4_9__leaf_clk clknet_leaf_0_clk clknet_leaf_100_clk clknet_leaf_101_clk clknet_leaf_102_clk clknet_leaf_103_clk clknet_leaf_104_clk clknet_leaf_105_clk clknet_leaf_106_clk clknet_leaf_107_clk clknet_leaf_108_clk clknet_leaf_109_clk clknet_leaf_10_clk clknet_leaf_110_clk clknet_leaf_111_clk clknet_leaf_112_clk clknet_leaf_113_clk clknet_leaf_114_clk clknet_leaf_115_clk clknet_leaf_116_clk clknet_leaf_117_clk clknet_leaf_119_clk clknet_leaf_11_clk clknet_leaf_120_clk clknet_leaf_121_clk clknet_leaf_122_clk clknet_leaf_123_clk clknet_leaf_124_clk clknet_leaf_125_clk clknet_leaf_126_clk clknet_leaf_127_clk clknet_leaf_128_clk clknet_leaf_129_clk clknet_leaf_12_clk clknet_leaf_130_clk clknet_leaf_131_clk clknet_leaf_132_clk clknet_leaf_133_clk clknet_leaf_134_clk clknet_leaf_135_clk clknet_leaf_136_clk clknet_leaf_137_clk clknet_leaf_138_clk clknet_leaf_139_clk clknet_leaf_13_clk clknet_leaf_140_clk clknet_leaf_141_clk clknet_leaf_143_clk clknet_leaf_144_clk clknet_leaf_145_clk clknet_leaf_146_clk clknet_leaf_147_clk clknet_leaf_148_clk clknet_leaf_149_clk clknet_leaf_14_clk clknet_leaf_150_clk clknet_leaf_151_clk clknet_leaf_152_clk clknet_leaf_153_clk clknet_leaf_154_clk clknet_leaf_156_clk clknet_leaf_157_clk clknet_leaf_158_clk clknet_leaf_159_clk clknet_leaf_15_clk clknet_leaf_160_clk clknet_leaf_161_clk clknet_leaf_162_clk clknet_leaf_163_clk clknet_leaf_164_clk clknet_leaf_165_clk clknet_leaf_166_clk clknet_leaf_167_clk clknet_leaf_168_clk clknet_leaf_169_clk clknet_leaf_16_clk clknet_leaf_170_clk clknet_leaf_171_clk clknet_leaf_172_clk clknet_leaf_173_clk clknet_leaf_174_clk clknet_leaf_175_clk clknet_leaf_176_clk clknet_leaf_177_clk clknet_leaf_178_clk clknet_leaf_179_clk clknet_leaf_17_clk clknet_leaf_180_clk clknet_leaf_181_clk clknet_leaf_182_clk clknet_leaf_183_clk clknet_leaf_184_clk clknet_leaf_185_clk clknet_leaf_186_clk clknet_leaf_187_clk clknet_leaf_188_clk clknet_leaf_189_clk clknet_leaf_18_clk clknet_leaf_190_clk clknet_leaf_191_clk clknet_leaf_192_clk clknet_leaf_193_clk clknet_leaf_194_clk clknet_leaf_195_clk clknet_leaf_196_clk clknet_leaf_197_clk clknet_leaf_198_clk clknet_leaf_199_clk clknet_leaf_19_clk clknet_leaf_1_clk clknet_leaf_200_clk clknet_leaf_201_clk clknet_leaf_202_clk clknet_leaf_203_clk clknet_leaf_204_clk clknet_leaf_205_clk clknet_leaf_207_clk clknet_leaf_208_clk clknet_leaf_209_clk clknet_leaf_20_clk clknet_leaf_210_clk clknet_leaf_211_clk clknet_leaf_212_clk clknet_leaf_213_clk clknet_leaf_214_clk clknet_leaf_215_clk clknet_leaf_216_clk clknet_leaf_217_clk clknet_leaf_218_clk clknet_leaf_219_clk clknet_leaf_21_clk clknet_leaf_220_clk clknet_leaf_221_clk clknet_leaf_22_clk clknet_leaf_23_clk clknet_leaf_24_clk clknet_leaf_25_clk clknet_leaf_26_clk clknet_leaf_27_clk clknet_leaf_28_clk clknet_leaf_29_clk clknet_leaf_2_clk clknet_leaf_30_clk clknet_leaf_31_clk clknet_leaf_32_clk clknet_leaf_33_clk clknet_leaf_34_clk clknet_leaf_35_clk clknet_leaf_36_clk clknet_leaf_37_clk clknet_leaf_38_clk clknet_leaf_39_clk clknet_leaf_3_clk clknet_leaf_40_clk clknet_leaf_41_clk clknet_leaf_42_clk clknet_leaf_43_clk clknet_leaf_44_clk clknet_leaf_45_clk clknet_leaf_46_clk clknet_leaf_47_clk clknet_leaf_49_clk clknet_leaf_4_clk clknet_leaf_50_clk clknet_leaf_51_clk clknet_leaf_52_clk clknet_leaf_53_clk clknet_leaf_54_clk clknet_leaf_55_clk clknet_leaf_56_clk clknet_leaf_57_clk clknet_leaf_58_clk clknet_leaf_59_clk clknet_leaf_5_clk clknet_leaf_60_clk clknet_leaf_61_clk clknet_leaf_62_clk clknet_leaf_63_clk clknet_leaf_64_clk clknet_leaf_65_clk clknet_leaf_66_clk clknet_leaf_67_clk clknet_leaf_68_clk clknet_leaf_69_clk clknet_leaf_6_clk clknet_leaf_70_clk clknet_leaf_71_clk clknet_leaf_72_clk clknet_leaf_73_clk clknet_leaf_74_clk clknet_leaf_75_clk clknet_leaf_76_clk clknet_leaf_77_clk clknet_leaf_78_clk clknet_leaf_79_clk clknet_leaf_7_clk clknet_leaf_80_clk clknet_leaf_81_clk clknet_leaf_82_clk clknet_leaf_83_clk clknet_leaf_84_clk clknet_leaf_85_clk clknet_leaf_86_clk clknet_leaf_87_clk clknet_leaf_88_clk clknet_leaf_89_clk clknet_leaf_8_clk clknet_leaf_90_clk clknet_leaf_91_clk clknet_leaf_92_clk clknet_leaf_93_clk clknet_leaf_94_clk clknet_leaf_95_clk clknet_leaf_96_clk clknet_leaf_97_clk clknet_leaf_98_clk clknet_leaf_99_clk clknet_leaf_9_clk net1 net10 net100 net1000 net1001 net1002 net1003 net1004 net1005 net1006 net1007 net1008 net1009 net101 net1010 net1011 net1012 net1013 net1014 net1015 net1016 net1017 net1018 net1019 net102 net1020 net1021 net1022 net1023 net1024 net1025 net1026 net1027 net1028 net1029 net103 net1030 net1031 net1032 net1033 net1034 net1035 net1036 net1037 net1038 net1039 net104 net1040 net1041 net1042 net1043 net1044 net1045 net1046 net1047 net1048 net1049 net105 net1050 net1051 net1052 net1053 net1054 net1055 net1056 net1057 net1058 net1059 net106 net1060 net1061 net1062 net1063 net1064 net1065 net1066 net1067 net1068 net1069 net107 net1070 net1071 net1072 net1073 net1074 net1075 net1076 net1077 net1078 net1079 net108 net1080 net1081 net1082 net1083 net1084 net1085 net1086 net1087 net1088 net1089 net109 net1090 net1091 net1092 net1093 net1094 net1095 net1096 net1097 net1098 net1099 net11 net110 net1100 net1101 net1102 net1103 net1104 net1105 net1106 net1107 net1108 net1109 net111 net1110 net1111 net1112 net1113 net1114 net1115 net1116 net1117 net1118 net1119 net112 net1120 net1121 net1122 net1123 net1124 net1125 net1126 net1127 net1128 net1129 net113 net1130 net1131 net1132 net1133 net1134 net1135 net1136 net1137 net1138 net1139 net114 net1140 net1141 net1142 net1143 net1144 net1145 net1146 net1147 net1148 net1149 net115 net1150 net1151 net1152 net1153 net1154 net1155 net1156 net1157 net1158 net1159 net116 net1160 net1161 net1162 net1163 net1164 net1165 net1166 net1167 net1168 net1169 net117 net1170 net1171 net1172 net1173 net1174 net1175 net1176 net1177 net1178 net1179 net118 net1180 net1181 net1182 net1183 net1184 net1185 net1186 net1187 net1188 net1189 net119 net1190 net1191 net1192 net1193 net1194 net1195 net1196 net1197 net1198 net1199 net12 net120 net1200 net1201 net1202 net1203 net1204 net1205 net1206 net1207 net1208 net1209 net121 net1210 net1211 net1212 net1213 net1214 net1215 net1216 net1217 net1218 net1219 net122 net1220 net1221 net1222 net1223 net1224 net1225 net1226 net1227 net1228 net1229 net123 net1230 net1231 net1232 net1233 net1234 net1235 net1236 net1237 net1238 net1239 net124 net1240 net1241 net1242 net1243 net1244 net1245 net1246 net1247 net1248 net1249 net125 net1250 net1251 net1252 net1253 net1254 net1255 net1256 net1257 net1258 net1259 net126 net1260 net1261 net1262 net1263 net1264 net1265 net1266 net1267 net1268 net1269 net127 net1270 net1271 net1272 net1273 net1274 net1275 net1276 net1277 net1278 net1279 net128 net1280 net1281 net1282 net1283 net1284 net1285 net1286 net1287 net1288 net1289 net129 net1290 net1291 net1292 net1293 net1294 net1295 net1296 net1297 net1298 net1299 net13 net130 net1300 net1301 net1302 net1303 net1304 net1305 net1306 net1307 net1308 net1309 net131 net1310 net1311 net1312 net1313 net1314 net1315 net1316 net1317 net1318 net1319 net132 net1320 net1321 net1322 net1323 net1324 net1325 net1326 net1327 net1328 net1329 net133 net1330 net1331 net1332 net1333 net1334 net1335 net1336 net1337 net1338 net1339 net134 net1340 net1341 net1342 net1343 net1344 net1345 net1346 net1347 net1348 net1349 net135 net1350 net1351 net1352 net1353 net1354 net1355 net1356 net1357 net1358 net1359 net136 net1360 net1361 net1362 net1363 net1364 net1365 net1366 net1367 net1368 net1369 net137 net1370 net1371 net1372 net1373 net1374 net1375 net1376 net1377 net1378 net1379 net138 net1380 net1381 net1382 net1383 net1384 net1385 net1386 net1387 net1388 net1389 net139 net1390 net1391 net1392 net1393 net1394 net1395 net1396 net1397 net1398 net1399 net14 net140 net1400 net1401 net1402 net1403 net1404 net1405 net1406 net1407 net1408 net1409 net141 net1410 net1411 net1412 net1413 net1414 net1415 net1416 net1417 net1418 net1419 net142 net1420 net1421 net1422 net1423 net1424 net1425 net1426 net1427 net1428 net1429 net143 net1430 net1431 net1432 net1433 net1434 net1435 net1436 net1437 net1438 net1439 net144 net1440 net1441 net1442 net1443 net1444 net1445 net1446 net1447 net1448 net1449 net145 net1450 net1451 net1452 net1453 net1454 net1455 net1456 net1457 net1458 net1459 net146 net1460 net1461 net1462 net1463 net1464 net1465 net1466 net1467 net1468 net1469 net147 net1470 net1471 net1472 net1473 net1474 net1475 net1476 net1477 net1478 net1479 net148 net1480 net1481 net1482 net1483 net1484 net1485 net1486 net1487 net1488 net1489 net149 net1490 net1491 net1492 net1493 net1494 net1495 net1496 net1497 net1498 net1499 net15 net150 net1500 net1501 net1502 net1503 net1504 net1505 net1506 net1507 net1508 net1509 net151 net1510 net1511 net1512 net1513 net1514 net1515 net1516 net1517 net1518 net1519 net152 net1520 net1521 net1522 net1523 net1524 net1525 net1526 net1527 net1528 net1529 net153 net1530 net1531 net1532 net154 net155 net156 net157 net158 net159 net16 net160 net161 net162 net163 net164 net165 net166 net167 net168 net169 net17 net170 net171 net172 net173 net174 net175 net176 net177 net178 net179 net18 net180 net181 net182 net183 net184 net185 net186 net187 net188 net189 net19 net190 net191 net192 net193 net194 net195 net196 net197 net198 net199 net2 net20 net200 net201 net202 net203 net204 net205 net206 net207 net208 net209 net21 net210 net211 net212 net213 net214 net215 net216 net217 net218 net219 net22 net220 net221 net222 net223 net224 net225 net226 net227 net228 net229 net23 net230 net231 net232 net233 net234 net235 net236 net237 net238 net239 net24 net240 net241 net242 net243 net244 net245 net246 net247 net248 net249 net25 net250 net251 net252 net253 net254 net255 net256 net257 net258 net259 net26 net260 net261 net262 net263 net264 net265 net266 net267 net268 net269 net27 net270 net271 net272 net273 net274 net275 net276 net277 net278 net279 net28 net280 net281 net282 net283 net284 net285 net286 net287 net288 net289 net29 net290 net291 net292 net293 net294 net295 net296 net297 net298 net299 net3 net30 net300 net301 net302 net303 net304 net305 net306 net307 net308 net309 net31 net310 net311 net312 net313 net314 net315 net316 net317 net318 net319 net32 net320 net321 net322 net323 net324 net325 net326 net327 net328 net329 net33 net330 net331 net332 net333 net334 net335 net336 net337 net338 net339 net34 net340 net341 net342 net343 net344 net345 net346 net347 net348 net349 net35 net350 net351 net352 net353 net354 net355 net356 net357 net358 net359 net36 net360 net361 net362 net363 net364 net365 net366 net367 net368 net369 net37 net370 net371 net372 net373 net374 net375 net376 net377 net378 net379 net38 net380 net381 net382 net383 net384 net385 net386 net387 net388 net389 net39 net390 net391 net392 net393 net394 net395 net396 net397 net398 net399 net4 net40 net400 net401 net402 net403 net404 net405 net406 net407 net408 net409 net41 net410 net411 net412 net413 net414 net415 net416 net417 net418 net419 net42 net420 net421 net422 net423 net424 net425 net426 net427 net428 net429 net43 net430 net431 net432 net433 net434 net435 net436 net437 net438 net439 net44 net440 net441 net442 net443 net444 net445 net446 net447 net448 net449 net45 net450 net451 net452 net453 net454 net455 net456 net457 net458 net459 net46 net460 net461 net462 net463 net464 net465 net466 net467 net468 net469 net47 net470 net471 net472 net473 net474 net475 net476 net477 net478 net479 net48 net480 net481 net482 net483 net484 net485 net486 net487 net488 net489 net49 net490 net491 net492 net493 net494 net495 net496 net497 net498 net499 net5 net50 net500 net501 net502 net503 net504 net505 net506 net507 net508 net509 net51 net510 net511 net512 net513 net514 net515 net516 net517 net518 net519 net52 net520 net521 net522 net523 net524 net525 net526 net527 net528 net529 net53 net530 net531 net532 net533 net534 net535 net536 net537 net538 net539 net54 net540 net541 net542 net543 net544 net545 net546 net547 net548 net549 net55 net550 net551 net552 net553 net554 net555 net556 net557 net558 net559 net56 net560 net561 net562 net563 net564 net565 net566 net567 net568 net569 net57 net570 net571 net572 net573 net574 net575 net576 net577 net578 net579 net58 net580 net581 net582 net583 net584 net585 net586 net587 net588 net589 net59 net590 net591 net592 net593 net594 net595 net596 net597 net598 net599 net6 net60 net600 net601 net602 net603 net604 net605 net606 net607 net608 net609 net61 net610 net611 net612 net613 net614 net615 net616 net617 net618 net619 net62 net620 net621 net622 net623 net624 net625 net626 net627 net628 net629 net63 net630 net631 net632 net633 net634 net635 net636 net637 net638 net639 net64 net640 net641 net642 net643 net644 net645 net646 net647 net648 net649 net65 net650 net651 net652 net653 net654 net655 net656 net657 net658 net659 net66 net660 net661 net662 net663 net664 net665 net666 net667 net668 net669 net67 net670 net671 net672 net673 net674 net675 net676 net677 net678 net679 net68 net680 net681 net682 net683 net684 net685 net686 net687 net688 net689 net69 net690 net691 net692 net693 net694 net695 net696 net697 net698 net699 net7 net70 net700 net701 net702 net703 net704 net705 net706 net707 net708 net709 net71 net710 net711 net712 net713 net714 net715 net716 net717 net718 net719 net72 net720 net721 net722 net723 net724 net725 net726 net727 net728 net729 net73 net730 net731 net732 net733 net734 net735 net736 net737 net738 net739 net74 net740 net741 net742 net743 net744 net745 net746 net747 net748 net749 net75 net750 net751 net752 net753 net754 net755 net756 net757 net758 net759 net76 net760 net761 net762 net763 net764 net765 net766 net767 net768 net769 net77 net770 net771 net772 net773 net774 net775 net776 net777 net778 net779 net78 net780 net781 net782 net783 net784 net785 net786 net787 net788 net789 net79 net790 net791 net792 net793 net794 net795 net796 net797 net798 net799 net8 net80 net800 net801 net802 net803 net804 net805 net806 net807 net808 net809 net81 net810 net811 net812 net813 net814 net815 net816 net817 net818 net819 net82 net820 net821 net822 net823 net824 net825 net826 net827 net828 net829 net83 net830 net831 net832 net833 net834 net835 net836 net837 net838 net839 net84 net840 net841 net842 net843 net844 net845 net846 net847 net848 net849 net85 net850 net851 net852 net853 net854 net855 net856 net857 net858 net859 net86 net860 net861 net862 net863 net864 net865 net866 net867 net868 net869 net87 net870 net871 net872 net873 net874 net875 net876 net877 net878 net879 net88 net880 net881 net882 net883 net884 net885 net886 net887 net888 net889 net89 net890 net891 net892 net893 net894 net895 net896 net897 net898 net899 net9 net90 net900 net901 net902 net903 net904 net905 net906 net907 net908 net909 net91 net910 net911 net912 net913 net914 net915 net916 net917 net918 net919 net92 net920 net921 net922 net923 net924 net925 net926 net927 net928 net929 net93 net930 net931 net932 net933 net934 net935 net936 net937 net938 net939 net94 net940 net941 net942 net943 net944 net945 net946 net947 net948 net949 net95 net950 net951 net952 net953 net954 net955 net956 net957 net958 net959 net96 net960 net961 net962 net963 net964 net965 net966 net967 net968 net969 net97 net970 net971 net972 net973 net974 net975 net976 net977 net978 net979 net98 net980 net981 net982 net983 net984 net985 net986 net987 net988 net989 net99 net990 net991 net992 net993 net994 net995 net996 net997 net998 net999
A5: A07 | B5: A07_dcim_top | C5: A07_dcim_top.gds | D5: 1110 | E5: 1110 | F5: =IFERROR(and(vlookup(D5,Blocks!E$2:E$12,1,0),vlookup(E5,Blocks!F$2:F$12,1,0)),false) -> TRUE | G5: =ifna(if(vlookup(A5,Export!B:B,1,0)<>"","OK"),"") -> OK | H5: =vlookup(A5,Status!A:C,3,0) | I5: =IFERROR(__xludf.DUMMYFUNCTION("IF(or(D5="""",J5=0,L5=""0:""),"""",IFNA(INDEX(FILTER(Blocks!$A$2:$A1006, Blocks!$E$2:$E1006>=D5, Blocks!$F$2:$F1006>=E5, Blocks!$D$2:$D1006>=J5),1),""X""))"),"A") -> A | J5: =left(K5,find(":",K5)-1)+left(L5,find(":",L5)-1)+left(M5,find(":",M5)-1)+left(N5,find(":",N5)-1)+left(O5,find(":",O5)-1)+left(P5,find(":",P5)-1)+left(Q5,find(":",Q5)-1)+left(R5,find(":",R5)-1) -> 14 | K5: 1:VDD | L5: 1:VSS | M5: 0: | N5: 0: | O5: 8:rst_n a_bit w_bit start cont P_minus1[0] P_minus1[1] P_minus1[2] | P5: 1:clk | Q5: 3:y_bit done busy | R5: 0: | S5: 0:
A6: A09 | B6: A09_BV | C6: A09_BV.gds | D6: 550 | E6: 1110 | F6: =IFERROR(and(vlookup(D6,Blocks!E$2:E$12,1,0),vlookup(E6,Blocks!F$2:F$12,1,0)),false) -> TRUE | G6: =ifna(if(vlookup(A6,Export!B:B,1,0)<>"","OK"),"") -> OK | H6: =vlookup(A6,Status!A:C,3,0) | I6: =IFERROR(__xludf.DUMMYFUNCTION("IF(or(D6="""",J6=0,L6=""0:""),"""",IFNA(INDEX(FILTER(Blocks!$A$2:$A1006, Blocks!$E$2:$E1006>=D6, Blocks!$F$2:$F1006>=E6, Blocks!$D$2:$D1006>=J6),1),""X""))"),"BV") -> BV | J6: =left(K6,find(":",K6)-1)+left(L6,find(":",L6)-1)+left(M6,find(":",M6)-1)+left(N6,find(":",N6)-1)+left(O6,find(":",O6)-1)+left(P6,find(":",P6)-1)+left(Q6,find(":",Q6)-1)+left(R6,find(":",R6)-1) -> 13 | K6: 1:VDD | L6: 1:VSS | M6: 0: | N6: 0: | O6: 2:rst_n uart_rx | P6: 1:clk | Q6: 8:uart_tx qspi_csn[0] qspi_csn[1] qspi_sck qspi_io[0] qspi_io[1] qspi_io[2] qspi_io[3] | R6: 0: | S6: 0:
A7: A10 | B7: A10_A | C7: A10_A.gds | D7: 1110 | E7: 1110 | F7: =IFERROR(and(vlookup(D7,Blocks!E$2:E$12,1,0),vlookup(E7,Blocks!F$2:F$12,1,0)),false) -> TRUE | G7: =ifna(if(vlookup(A7,Export!B:B,1,0)<>"","OK"),"") -> OK | H7: =vlookup(A7,Status!A:C,3,0) | I7: =IFERROR(__xludf.DUMMYFUNCTION("IF(or(D7="""",J7=0,L7=""0:""),"""",IFNA(INDEX(FILTER(Blocks!$A$2:$A1006, Blocks!$E$2:$E1006>=D7, Blocks!$F$2:$F1006>=E7, Blocks!$D$2:$D1006>=J7),1),""X""))"),"A") -> A | J7: =left(K7,find(":",K7)-1)+left(L7,find(":",L7)-1)+left(M7,find(":",M7)-1)+left(N7,find(":",N7)-1)+left(O7,find(":",O7)-1)+left(P7,find(":",P7)-1)+left(Q7,find(":",Q7)-1)+left(R7,find(":",R7)-1) -> 8 | K7: 1:VDD | L7: 1:VSS | M7: 0: | N7: 0: | O7: 0: | P7: 0: | Q7: 0: | R7: 6:clk rst_n sclk mosi cs_n miso | S7: 0:
A8: A12 | B8: grouper_soc_chip_core | C8: grouper_soc_chip_core.gds | D8: 1650 | E8: 1100 | F8: =IFERROR(and(vlookup(D8,Blocks!E$2:E$12,1,0),vlookup(E8,Blocks!F$2:F$12,1,0)),false) -> FALSE | G8: =ifna(if(vlookup(A8,Export!B:B,1,0)<>"","OK"),"") -> OK | H8: =vlookup(A8,Status!A:C,3,0) | I8: =IFERROR(__xludf.DUMMYFUNCTION("IF(or(D8="""",J8=0,L8=""0:""),"""",IFNA(INDEX(FILTER(Blocks!$A$2:$A1006, Blocks!$E$2:$E1006>=D8, Blocks!$F$2:$F1006>=E8, Blocks!$D$2:$D1006>=J8),1),""X""))"),"ACV") -> ACV | J8: =left(K8,find(":",K8)-1)+left(L8,find(":",L8)-1)+left(M8,find(":",M8)-1)+left(N8,find(":",N8)-1)+left(O8,find(":",O8)-1)+left(P8,find(":",P8)-1)+left(Q8,find(":",Q8)-1)+left(R8,find(":",R8)-1) -> 22 | K8: 1:VDD | L8: 1:VSS | M8: 0: | N8: 0: | O8: 1:uart_rx | P8: 2:clk rst_n | Q8: 17:uart_tx *gpio_0 *gpio_1 *gpio_2 *gpio_3 *gpio_4 *gpio_5 *gpio_6 *gpio_7 *gpio_8 *gpio_9 *gpio_10 *gpio_11 *gpio_12 *gpio_13 *gpio_14 *gpio_15 | R8: 0: | S8: 128:gpio_0_bidir_cs gpio_0_bidir_ie gpio_0_bidir_in gpio_0_bidir_oe gpio_0_bidir_out gpio_0_bidir_pd gpio_0_bidir_pu gpio_0_bidir_sl gpio_10_bidir_cs gpio_10_bidir_ie gpio_10_bidir_in gpio_10_bidir_oe gpio_10_bidir_out gpio_10_bidir_pd gpio_10_bidir_pu gpio_10_bidir_sl gpio_11_bidir_cs gpio_11_bidir_ie gpio_11_bidir_in gpio_11_bidir_oe gpio_11_bidir_out gpio_11_bidir_pd gpio_11_bidir_pu gpio_11_bidir_sl gpio_12_bidir_cs gpio_12_bidir_ie gpio_12_bidir_in gpio_12_bidir_oe gpio_12_bidir_out gpio_12_bidir_pd gpio_12_bidir_pu gpio_12_bidir_sl gpio_13_bidir_cs gpio_13_bidir_ie gpio_13_bidir_in gpio_13_bidir_oe gpio_13_bidir_out gpio_13_bidir_pd gpio_13_bidir_pu gpio_13_bidir_sl gpio_14_bidir_cs gpio_14_bidir_ie gpio_14_bidir_in gpio_14_bidir_oe gpio_14_bidir_out gpio_14_bidir_pd gpio_14_bidir_pu gpio_14_bidir_sl gpio_15_bidir_cs gpio_15_bidir_ie gpio_15_bidir_in gpio_15_bidir_oe gpio_15_bidir_out gpio_15_bidir_pd gpio_15_bidir_pu gpio_15_bidir_sl gpio_1_bidir_cs gpio_1_bidir_ie gpio_1_bidir_in gpio_1_bidir_oe gpio_1_bidir_out gpio_1_bidir_pd gpio_1_bidir_pu gpio_1_bidir_sl gpio_2_bidir_cs gpio_2_bidir_ie gpio_2_bidir_in gpio_2_bidir_oe gpio_2_bidir_out gpio_2_bidir_pd gpio_2_bidir_pu gpio_2_bidir_sl gpio_3_bidir_cs gpio_3_bidir_ie gpio_3_bidir_in gpio_3_bidir_oe gpio_3_bidir_out gpio_3_bidir_pd gpio_3_bidir_pu gpio_3_bidir_sl gpio_4_bidir_cs gpio_4_bidir_ie gpio_4_bidir_in gpio_4_bidir_oe gpio_4_bidir_out gpio_4_bidir_pd gpio_4_bidir_pu gpio_4_bidir_sl gpio_5_bidir_cs gpio_5_bidir_ie gpio_5_bidir_in gpio_5_bidir_oe gpio_5_bidir_out gpio_5_bidir_pd gpio_5_bidir_pu gpio_5_bidir_sl gpio_6_bidir_cs gpio_6_bidir_ie gpio_6_bidir_in gpio_6_bidir_oe gpio_6_bidir_out gpio_6_bidir_pd gpio_6_bidir_pu gpio_6_bidir_sl gpio_7_bidir_cs gpio_7_bidir_ie gpio_7_bidir_in gpio_7_bidir_oe gpio_7_bidir_out gpio_7_bidir_pd gpio_7_bidir_pu gpio_7_bidir_sl gpio_8_bidir_cs gpio_8_bidir_ie gpio_8_bidir_in gpio_8_bidir_oe gpio_8_bidir_out gpio_8_bidir_pd gpio_8_bidir_pu gpio_8_bidir_sl gpio_9_bidir_cs gpio_9_bidir_ie gpio_9_bidir_in gpio_9_bidir_oe gpio_9_bidir_out gpio_9_bidir_pd gpio_9_bidir_pu gpio_9_bidir_sl | T8: missing gpio_0_IN|gpio_0_OUT; missing gpio_1_IN|gpio_1_OUT; missing gpio_2_IN|gpio_2_OUT; missing gpio_3_IN|gpio_3_OUT; missing gpio_4_IN|gpio_4_OUT; missing gpio_5_IN|gpio_5_OUT; missing gpio_6_IN|gpio_6_OUT; missing gpio_7_IN|gpio_7_OUT; missing gpio_8_IN|gpio_8_OUT; missing gpio_9_IN|gpio_9_OUT; missing gpio_10_IN|gpio_10_OUT; missing gpio_11_IN|gpio_11_OUT; missing gpio_12_IN|gpio_12_OUT; missing gpio_13_IN|gpio_13_OUT; missing gpio_14_IN|gpio_14_OUT; missing gpio_15_IN|gpio_15_OUT
A9: A13 | B9: adc_top | C9: adc_chip_top.gds | D9: 514.25 | E9: 549.7 | F9: =IFERROR(and(vlookup(D9,Blocks!E$2:E$12,1,0),vlookup(E9,Blocks!F$2:F$12,1,0)),false) -> FALSE | G9: =ifna(if(vlookup(A9,Export!B:B,1,0)<>"","OK"),"") -> OK | H9: =vlookup(A9,Status!A:C,3,0) | I9: =IFERROR(__xludf.DUMMYFUNCTION("IF(or(D9="""",J9=0,L9=""0:""),"""",IFNA(INDEX(FILTER(Blocks!$A$2:$A1006, Blocks!$E$2:$E1006>=D9, Blocks!$F$2:$F1006>=E9, Blocks!$D$2:$D1006>=J9),1),""X""))"),"BV") -> BV | J9: =left(K9,find(":",K9)-1)+left(L9,find(":",L9)-1)+left(M9,find(":",M9)-1)+left(N9,find(":",N9)-1)+left(O9,find(":",O9)-1)+left(P9,find(":",P9)-1)+left(Q9,find(":",Q9)-1)+left(R9,find(":",R9)-1) -> 14 | K9: 1:VDD | L9: 1:VSS | M9: 0: | N9: 1:VIN | O9: 1:RST_N | P9: 1:CLK | Q9: 9:EOC BIT_0 BIT_1 BIT_2 BIT_3 BIT_4 BIT_5 BIT_6 BIT_7 | R9: 0: | S9: 0:
A10: A19 | B10: chip_top | C10: chip_top.gds | D10: 2084 | E10: 2084 | F10: =IFERROR(and(vlookup(D10,Blocks!E$2:E$12,1,0),vlookup(E10,Blocks!F$2:F$12,1,0)),false) -> FALSE | G10: =ifna(if(vlookup(A10,Export!B:B,1,0)<>"","OK"),"") | H10: =vlookup(A10,Status!A:C,3,0) | I10: =IFERROR(__xludf.DUMMYFUNCTION("IF(or(D10="""",J10=0,L10=""0:""),"""",IFNA(INDEX(FILTER(Blocks!$A$2:$A1006, Blocks!$E$2:$E1006>=D10, Blocks!$F$2:$F1006>=E10, Blocks!$D$2:$D1006>=J10),1),""X""))"),"ACE2") -> ACE2 | J10: =left(K10,find(":",K10)-1)+left(L10,find(":",L10)-1)+left(M10,find(":",M10)-1)+left(N10,find(":",N10)-1)+left(O10,find(":",O10)-1)+left(P10,find(":",P10)-1)+left(Q10,find(":",Q10)-1)+left(R10,find(":",R10)-1) -> 32 | K10: 1:VDD | L10: 1:VSS | M10: 11:*W09_NC *W10_NC *W12_NC *W13_NC *W15_NC *W16_NC *N01_NC *N02_NC *N03_NC *N04_NC *N13_NC | N10: 0: | O10: 6:*rst_n *a_valid_i *a_last_i *b_valid_i *b_last_i *out_ready_i | P10: 1:*clk | Q10: 0: | R10: 12:*a_ready_o *b_ready_o *data[0] *data[1] *data[2] *data[3] *data[4] *data[5] *data[6] *data[7] *out_valid_o *out_last_o | S10: 20:analog_PAD bidir_PAD[0] bidir_PAD[10] bidir_PAD[11] bidir_PAD[1] bidir_PAD[2] bidir_PAD[3] bidir_PAD[4] bidir_PAD[5] bidir_PAD[6] bidir_PAD[7] bidir_PAD[8] bidir_PAD[9] clk_PAD input_PAD[0] input_PAD[1] input_PAD[2] input_PAD[3] input_PAD[4] rst_n_PAD | T10: missing W09_NC; missing W10_NC; missing rst_n; missing W12_NC; missing W13_NC; missing clk; missing W15_NC; missing W16_NC; missing a_valid_i; missing a_last_i; missing a_ready_o_IN|a_ready_o_OUT; missing b_valid_i; missing b_last_i; missing b_ready_o_IN|b_ready_o_OUT; missing N01_NC; missing N02_NC; missing N03_NC; missing N04_NC; missing data_IN[0]|data_OUT[0]; missing data_IN[1]|data_OUT[1]; missing data_IN[2]|data_OUT[2]; missing data_IN[3]|data_OUT[3]; missing data_IN[4]|data_OUT[4]; missing data_IN[5]|data_OUT[5]; missing data_IN[6]|data_OUT[6]; missing data_IN[7]|data_OUT[7]; missing N13_NC; missing out_valid_o_IN|out_valid_o_OUT; missing out_last_o_IN|out_last_o_OUT; missing out_ready_i
A11: A20 | B11: system_top | C11: system_top.gds | D11: 1100 | E11: 550 | F11: =IFERROR(and(vlookup(D11,Blocks!E$2:E$12,1,0),vlookup(E11,Blocks!F$2:F$12,1,0)),false) -> FALSE | G11: =ifna(if(vlookup(A11,Export!B:B,1,0)<>"","OK"),"") -> OK | H11: =vlookup(A11,Status!A:C,3,0) | I11: =IFERROR(__xludf.DUMMYFUNCTION("IF(or(D11="""",J11=0,L11=""0:""),"""",IFNA(INDEX(FILTER(Blocks!$A$2:$A1006, Blocks!$E$2:$E1006>=D11, Blocks!$F$2:$F1006>=E11, Blocks!$D$2:$D1006>=J11),1),""X""))"),"BH") -> BH | J11: =left(K11,find(":",K11)-1)+left(L11,find(":",L11)-1)+left(M11,find(":",M11)-1)+left(N11,find(":",N11)-1)+left(O11,find(":",O11)-1)+left(P11,find(":",P11)-1)+left(Q11,find(":",Q11)-1)+left(R11,find(":",R11)-1) -> 9 | K11: 1:*vdd | L11: 1:*vss | M11: 0: | N11: 0: | O11: 6:clk rst_n uart_rx mosi sck cs_n | P11: 0: | Q11: 0: | R11: 1:miso | S11: 2:VDD VSS | T11: missing vss; missing vdd
A12: A23 | B12: sar_adc_10b | C12: sar_adc_10b.gds | F12: =IFERROR(and(vlookup(D12,Blocks!E$2:E$12,1,0),vlookup(E12,Blocks!F$2:F$12,1,0)),false) -> FALSE | G12: =ifna(if(vlookup(A12,Export!B:B,1,0)<>"","OK"),"") | H12: =vlookup(A12,Status!A:C,3,0) | I12: =IFERROR(__xludf.DUMMYFUNCTION("IF(or(D12="""",J12=0,L12=""0:""),"""",IFNA(INDEX(FILTER(Blocks!$A$2:$A1006, Blocks!$E$2:$E1006>=D12, Blocks!$F$2:$F1006>=E12, Blocks!$D$2:$D1006>=J12),1),""X""))"),"") | J12: =left(K12,find(":",K12)-1)+left(L12,find(":",L12)-1)+left(M12,find(":",M12)-1)+left(N12,find(":",N12)-1)+left(O12,find(":",O12)-1)+left(P12,find(":",P12)-1)+left(Q12,find(":",Q12)-1)+left(R12,find(":",R12)-1) -> 18 | K12: 1:VDD | L12: 1:VSS | M12: 0: | N12: 3:Vin VRP VRN | O12: 2:CLK SAMP | P12: 0: | Q12: 11:B[9] B[8] B[7] B[6] B[5] B[4] B[3] B[2] B[1] B[0] eoc | R12: 0: | S12: 0: | T12: TOP_LAYOUT 'sar_adc_10b' has no top-level shapes on layer 0/datatype 0
A13: A28 | B13: bgr_top_firstcut | C13: bgr_top_firstcut.gds | F13: =IFERROR(and(vlookup(D13,Blocks!E$2:E$12,1,0),vlookup(E13,Blocks!F$2:F$12,1,0)),false) -> FALSE | G13: =ifna(if(vlookup(A13,Export!B:B,1,0)<>"","OK"),"") | H13: =vlookup(A13,Status!A:C,3,0) | I13: =IFERROR(__xludf.DUMMYFUNCTION("IF(or(D13="""",J13=0,L13=""0:""),"""",IFNA(INDEX(FILTER(Blocks!$A$2:$A1006, Blocks!$E$2:$E1006>=D13, Blocks!$F$2:$F1006>=E13, Blocks!$D$2:$D1006>=J13),1),""X""))"),"") | J13: =left(K13,find(":",K13)-1)+left(L13,find(":",L13)-1)+left(M13,find(":",M13)-1)+left(N13,find(":",N13)-1)+left(O13,find(":",O13)-1)+left(P13,find(":",P13)-1)+left(Q13,find(":",Q13)-1)+left(R13,find(":",R13)-1) -> 0 | K13: 0: | L13: 0: | M13: 0: | N13: 0: | O13: 0: | P13: 0: | Q13: 0: | R13: 0: | S13: 0: | T13: info.yaml does not contain a pin list (expected 'pins' or 'project.pins'); TOP_LAYOUT 'bgr_top_firstcut' has no top-level shapes on layer 0/datatype 0
A14: A30 | B14: qspi_chip_top | C14: qspi_chip_top.gds | D14: 1100 | E14: 1100 | F14: =IFERROR(and(vlookup(D14,Blocks!E$2:E$12,1,0),vlookup(E14,Blocks!F$2:F$12,1,0)),false) -> FALSE | G14: =ifna(if(vlookup(A14,Export!B:B,1,0)<>"","OK"),"") -> OK | H14: =vlookup(A14,Status!A:C,3,0) | I14: =IFERROR(__xludf.DUMMYFUNCTION("IF(or(D14="""",J14=0,L14=""0:""),"""",IFNA(INDEX(FILTER(Blocks!$A$2:$A1006, Blocks!$E$2:$E1006>=D14, Blocks!$F$2:$F1006>=E14, Blocks!$D$2:$D1006>=J14),1),""X""))"),"A") -> A | J14: =left(K14,find(":",K14)-1)+left(L14,find(":",L14)-1)+left(M14,find(":",M14)-1)+left(N14,find(":",N14)-1)+left(O14,find(":",O14)-1)+left(P14,find(":",P14)-1)+left(Q14,find(":",Q14)-1)+left(R14,find(":",R14)-1) -> 18 | K14: 1:VDD | L14: 1:VSS | M14: 0: | N14: 0: | O14: 1:reset | P14: 1:clk | Q14: 2:uart_rx spi_miso | R14: 12:spi_data0 spi_data1 spi_data2 spi_data3 spi_clk_out spi_flash_select spi_ram_a_select uart_tx spi_select disp_spi_clk_out spi_mosi spi_dc | S14: 0:
A15: A34 | B15: chip_core | C15: chip_core.gds | D15: 1675 | E15: 1675 | F15: =IFERROR(and(vlookup(D15,Blocks!E$2:E$12,1,0),vlookup(E15,Blocks!F$2:F$12,1,0)),false) -> TRUE | G15: =ifna(if(vlookup(A15,Export!B:B,1,0)<>"","OK"),"") -> OK | H15: =vlookup(A15,Status!A:C,3,0) | I15: =IFERROR(__xludf.DUMMYFUNCTION("IF(or(D15="""",J15=0,L15=""0:""),"""",IFNA(INDEX(FILTER(Blocks!$A$2:$A1006, Blocks!$E$2:$E1006>=D15, Blocks!$F$2:$F1006>=E15, Blocks!$D$2:$D1006>=J15),1),""X""))"),"ACE") -> ACE | J15: =left(K15,find(":",K15)-1)+left(L15,find(":",L15)-1)+left(M15,find(":",M15)-1)+left(N15,find(":",N15)-1)+left(O15,find(":",O15)-1)+left(P15,find(":",P15)-1)+left(Q15,find(":",Q15)-1)+left(R15,find(":",R15)-1) -> 16 | K15: 1:VDD | L15: 1:VSS | M15: 0: | N15: 0: | O15: 9:clk input_in_0 input_in_1 input_in_2 input_in_3 input_in_4 input_in_5 input_in_6 input_in_7 | P15: 1:rst_n | Q15: 4:output_out_0 output_out_1 output_out_2 output_out_3 | R15: 0: | S15: 0:
A16: A37 | B16: integration_final | C16: integration_final.gds | D16: 1000 | E16: 1000 | F16: =IFERROR(and(vlookup(D16,Blocks!E$2:E$12,1,0),vlookup(E16,Blocks!F$2:F$12,1,0)),false) -> FALSE | G16: =ifna(if(vlookup(A16,Export!B:B,1,0)<>"","OK"),"") -> OK | H16: =vlookup(A16,Status!A:C,3,0) | I16: =IFERROR(__xludf.DUMMYFUNCTION("IF(or(D16="""",J16=0,L16=""0:""),"""",IFNA(INDEX(FILTER(Blocks!$A$2:$A1006, Blocks!$E$2:$E1006>=D16, Blocks!$F$2:$F1006>=E16, Blocks!$D$2:$D1006>=J16),1),""X""))"),"A") -> A | J16: =left(K16,find(":",K16)-1)+left(L16,find(":",L16)-1)+left(M16,find(":",M16)-1)+left(N16,find(":",N16)-1)+left(O16,find(":",O16)-1)+left(P16,find(":",P16)-1)+left(Q16,find(":",Q16)-1)+left(R16,find(":",R16)-1) -> 6 | K16: 1:VDD | L16: 1:VSS | M16: 0: | N16: 0: | O16: 3:i_clk i_rst_n i_uart_rx | P16: 0: | Q16: 1:o_uart_tx | R16: 0: | S16: 0:
A17: A40 | B17: trouper_top | C17: trouper_top.gds | D17: 1650 | E17: 1100 | F17: =IFERROR(and(vlookup(D17,Blocks!E$2:E$12,1,0),vlookup(E17,Blocks!F$2:F$12,1,0)),false) -> FALSE | G17: =ifna(if(vlookup(A17,Export!B:B,1,0)<>"","OK"),"") -> OK | H17: =vlookup(A17,Status!A:C,3,0) | I17: =IFERROR(__xludf.DUMMYFUNCTION("IF(or(D17="""",J17=0,L17=""0:""),"""",IFNA(INDEX(FILTER(Blocks!$A$2:$A1006, Blocks!$E$2:$E1006>=D17, Blocks!$F$2:$F1006>=E17, Blocks!$D$2:$D1006>=J17),1),""X""))"),"ACV") -> ACV | J17: =left(K17,find(":",K17)-1)+left(L17,find(":",L17)-1)+left(M17,find(":",M17)-1)+left(N17,find(":",N17)-1)+left(O17,find(":",O17)-1)+left(P17,find(":",P17)-1)+left(Q17,find(":",Q17)-1)+left(R17,find(":",R17)-1) -> 25 | K17: 1:VDD | L17: 1:VSS | M17: 0: | N17: 0: | O17: 10:IQ_DATA_I_0 IQ_DATA_Q_0 IQ_DATA_I_1 IQ_DATA_Q_1 IQ_DATA_I_2 IQ_DATA_Q_2 IQ_DATA_I_3 IQ_DATA_Q_3 IQ_CLK SPI_MOSI | P17: 3:RESETB HOST_CS SPI_SCK | Q17: 9:REMOD_A_I REMOD_A_Q PSRAM_CE_N *PSRAM_SIO_0 *PSRAM_SIO_1 *PSRAM_SIO_2 *PSRAM_SIO_3 SPI_MISO IRQ_OUT | R17: 1:PSRAM_SCK | S17: 40:GRP_ADDR_0 GRP_ADDR_1 GRP_ADDR_2 GRP_ADDR_3 GRP_ADDR_4 GRP_ADDR_5 GRP_ADDR_6 GRP_ADDR_7 GRP_RDATA_0 GRP_RDATA_1 GRP_RDATA_2 GRP_RDATA_3 GRP_RDATA_4 GRP_RDATA_5 GRP_RDATA_6 GRP_RDATA_7 GRP_RE GRP_READY GRP_WDATA_0 GRP_WDATA_1 GRP_WDATA_2 GRP_WDATA_3 GRP_WDATA_4 GRP_WDATA_5 GRP_WDATA_6 GRP_WDATA_7 GRP_WE IRQ_GROUPER PSRAM_SIO_IN_0 PSRAM_SIO_IN_1 PSRAM_SIO_IN_2 PSRAM_SIO_IN_3 PSRAM_SIO_OE_0 PSRAM_SIO_OE_1 PSRAM_SIO_OE_2 PSRAM_SIO_OE_3 PSRAM_SIO_OUT_0 PSRAM_SIO_OUT_1 PSRAM_SIO_OUT_2 PSRAM_SIO_OUT_3 | T17: missing PSRAM_SIO_0_IN|PSRAM_SIO_0_OUT; missing PSRAM_SIO_1_IN|PSRAM_SIO_1_OUT; missing PSRAM_SIO_2_IN|PSRAM_SIO_2_OUT; missing PSRAM_SIO_3_IN|PSRAM_SIO_3_OUT
A18: A43 | B18: ic_top_usb_audio | C18: ic_top_usb_audio.gds | D18: 1400 | E18: 500 | F18: =IFERROR(and(vlookup(D18,Blocks!E$2:E$12,1,0),vlookup(E18,Blocks!F$2:F$12,1,0)),false) -> FALSE | G18: =ifna(if(vlookup(A18,Export!B:B,1,0)<>"","OK"),"") -> OK | H18: =vlookup(A18,Status!A:C,3,0) | I18: =IFERROR(__xludf.DUMMYFUNCTION("IF(or(D18="""",J18=0,L18=""0:""),"""",IFNA(INDEX(FILTER(Blocks!$A$2:$A1006, Blocks!$E$2:$E1006>=D18, Blocks!$F$2:$F1006>=E18, Blocks!$D$2:$D1006>=J18),1),""X""))"),"ACV") -> ACV | J18: =left(K18,find(":",K18)-1)+left(L18,find(":",L18)-1)+left(M18,find(":",M18)-1)+left(N18,find(":",N18)-1)+left(O18,find(":",O18)-1)+left(P18,find(":",P18)-1)+left(Q18,find(":",Q18)-1)+left(R18,find(":",R18)-1) -> 10 | K18: 1:VDD | L18: 1:VSS | M18: 1:*AUDIO_OUT_L | N18: 0: | O18: 2:RESET_N *DAC_FB_IN_L | P18: 1:SYS_CLK_60M | Q18: 4:USB_DP_PULL DAC_MOD_OUT_L USB_DP USB_DN | R18: 0: | S18: 0: | T18: missing AUDIO_OUT_L; missing DAC_FB_IN_L
A19: A44 | B19: A44_SAR_ADC_CORE_1000_R3_DUMMY_FILL_REPAIR | C19: A44_SAR_ADC_CORE_1000.gds | D19: 1000 | E19: 1000 | F19: =IFERROR(and(vlookup(D19,Blocks!E$2:E$12,1,0),vlookup(E19,Blocks!F$2:F$12,1,0)),false) -> FALSE | G19: =ifna(if(vlookup(A19,Export!B:B,1,0)<>"","OK"),"") -> OK | H19: =vlookup(A19,Status!A:C,3,0) | I19: =IFERROR(__xludf.DUMMYFUNCTION("IF(or(D19="""",J19=0,L19=""0:""),"""",IFNA(INDEX(FILTER(Blocks!$A$2:$A1006, Blocks!$E$2:$E1006>=D19, Blocks!$F$2:$F1006>=E19, Blocks!$D$2:$D1006>=J19),1),""X""))"),"A") -> A | J19: =left(K19,find(":",K19)-1)+left(L19,find(":",L19)-1)+left(M19,find(":",M19)-1)+left(N19,find(":",N19)-1)+left(O19,find(":",O19)-1)+left(P19,find(":",P19)-1)+left(Q19,find(":",Q19)-1)+left(R19,find(":",R19)-1) -> 15 | K19: 1:VDD | L19: 1:GND | M19: 0: | N19: 4:VREFN VINN VINP VREFP | O19: 1:CLKS | P19: 0: | Q19: 8:DOUT[7] DOUT[6] DOUT[5] DOUT[4] DOUT[3] DOUT[2] DOUT[1] DOUT[0] | R19: 0: | S19: 20:CLKS_CORE CMPCK DCMPN DCMPP DCTRLN[1] DCTRLN[2] DCTRLN[3] DCTRLN[4] DCTRLN[5] DCTRLN[6] DCTRLN[7] DCTRLP[1] DCTRLP[2] DCTRLP[3] DCTRLP[4] DCTRLP[5] DCTRLP[6] DCTRLP[7] VFON VFOP
A20: A45 | B20: chip_top_full | C20: chip_top_full.gds | D20: 1100 | E20: 1100 | F20: =IFERROR(and(vlookup(D20,Blocks!E$2:E$12,1,0),vlookup(E20,Blocks!F$2:F$12,1,0)),false) -> FALSE | G20: =ifna(if(vlookup(A20,Export!B:B,1,0)<>"","OK"),"") | H20: =vlookup(A20,Status!A:C,3,0) | I20: =IFERROR(__xludf.DUMMYFUNCTION("IF(or(D20="""",J20=0,L20=""0:""),"""",IFNA(INDEX(FILTER(Blocks!$A$2:$A1006, Blocks!$E$2:$E1006>=D20, Blocks!$F$2:$F1006>=E20, Blocks!$D$2:$D1006>=J20),1),""X""))"),"A") -> A | J20: =left(K20,find(":",K20)-1)+left(L20,find(":",L20)-1)+left(M20,find(":",M20)-1)+left(N20,find(":",N20)-1)+left(O20,find(":",O20)-1)+left(P20,find(":",P20)-1)+left(Q20,find(":",Q20)-1)+left(R20,find(":",R20)-1) -> 22 | K20: 1:VDD | L20: 1:VSS | M20: 0: | N20: 0: | O20: 9:clk_int scan_in scan_shift scan_load scan_i0o1 gpio_in[0] gpio_in[1] uart_rx spi_miso | P20: 2:clk rst_n | Q20: 9:scan_out gpio_out[0] gpio_out[1] gpio_out[2] gpio_out[3] uart_tx spi_sclk spi_mosi spi_cs_n | R20: 0: | S20: 0:
A21: A48 | B21: trc_top | C21: trc_top.gds | D21: 550 | E21: 550 | F21: =IFERROR(and(vlookup(D21,Blocks!E$2:E$12,1,0),vlookup(E21,Blocks!F$2:F$12,1,0)),false) -> TRUE | G21: =ifna(if(vlookup(A21,Export!B:B,1,0)<>"","OK"),"") | H21: =vlookup(A21,Status!A:C,3,0) | I21: =IFERROR(__xludf.DUMMYFUNCTION("IF(or(D21="""",J21=0,L21=""0:""),"""",IFNA(INDEX(FILTER(Blocks!$A$2:$A1006, Blocks!$E$2:$E1006>=D21, Blocks!$F$2:$F1006>=E21, Blocks!$D$2:$D1006>=J21),1),""X""))"),"D") -> D | J21: =left(K21,find(":",K21)-1)+left(L21,find(":",L21)-1)+left(M21,find(":",M21)-1)+left(N21,find(":",N21)-1)+left(O21,find(":",O21)-1)+left(P21,find(":",P21)-1)+left(Q21,find(":",Q21)-1)+left(R21,find(":",R21)-1) -> 9 | K21: 1:VDD | L21: 1:VSS | M21: 0: | N21: 0: | O21: 3:iRST iSPI_CS iSPI_MOSI | P21: 2:iCLK iSPI_SCK | Q21: 2:oSPI_MISO oINTERRUPT | R21: 0: | S21: 0:
A22: A49 | B22: sar_adc_top | C22: sar_adc_top.gds | F22: =IFERROR(and(vlookup(D22,Blocks!E$2:E$12,1,0),vlookup(E22,Blocks!F$2:F$12,1,0)),false) -> FALSE | G22: =ifna(if(vlookup(A22,Export!B:B,1,0)<>"","OK"),"") -> OK | H22: =vlookup(A22,Status!A:C,3,0) | I22: =IFERROR(__xludf.DUMMYFUNCTION("IF(or(D22="""",J22=0,L22=""0:""),"""",IFNA(INDEX(FILTER(Blocks!$A$2:$A1006, Blocks!$E$2:$E1006>=D22, Blocks!$F$2:$F1006>=E22, Blocks!$D$2:$D1006>=J22),1),""X""))"),"") | J22: =left(K22,find(":",K22)-1)+left(L22,find(":",L22)-1)+left(M22,find(":",M22)-1)+left(N22,find(":",N22)-1)+left(O22,find(":",O22)-1)+left(P22,find(":",P22)-1)+left(Q22,find(":",Q22)-1)+left(R22,find(":",R22)-1) -> 14 | K22: 1:vdd | L22: 1:vss | M22: 0: | N22: 2:vref vin | O22: 0: | P22: 1:start | Q22: 9:done dout[0] dout[1] dout[2] dout[3] dout[4] dout[5] dout[6] dout[7] | R22: 0: | S22: 0: | T22: no layer 0/datatype 0 exists in GDS for TOP_LAYOUT 'sar_adc_top'
A23: A53 | B23: A53_trng_top | C23: A53_trng_top.gds | D23: 535.23 | E23: 533.55 | F23: =IFERROR(and(vlookup(D23,Blocks!E$2:E$12,1,0),vlookup(E23,Blocks!F$2:F$12,1,0)),false) -> FALSE | G23: =ifna(if(vlookup(A23,Export!B:B,1,0)<>"","OK"),"") -> OK | H23: =vlookup(A23,Status!A:C,3,0) | I23: =IFERROR(__xludf.DUMMYFUNCTION("IF(or(D23="""",J23=0,L23=""0:""),"""",IFNA(INDEX(FILTER(Blocks!$A$2:$A1006, Blocks!$E$2:$E1006>=D23, Blocks!$F$2:$F1006>=E23, Blocks!$D$2:$D1006>=J23),1),""X""))"),"D") -> D | J23: =left(K23,find(":",K23)-1)+left(L23,find(":",L23)-1)+left(M23,find(":",M23)-1)+left(N23,find(":",N23)-1)+left(O23,find(":",O23)-1)+left(P23,find(":",P23)-1)+left(Q23,find(":",Q23)-1)+left(R23,find(":",R23)-1) -> 10 | K23: 1:VDD | L23: 1:GND | M23: 2:vin_vco analog_raw_out | N23: 0: | O23: 4:rst_n clk test_data_in test_mode_en | P23: 0: | Q23: 2:data_serial_out bist_flag_out | R23: 0: | S23: 0:
A24: A54 | B24: lstm16x_top | C24: lstm16x_top.gds | D24: 1000 | E24: 1000 | F24: =IFERROR(and(vlookup(D24,Blocks!E$2:E$12,1,0),vlookup(E24,Blocks!F$2:F$12,1,0)),false) -> FALSE | G24: =ifna(if(vlookup(A24,Export!B:B,1,0)<>"","OK"),"") -> OK | H24: =vlookup(A24,Status!A:C,3,0) | I24: =IFERROR(__xludf.DUMMYFUNCTION("IF(or(D24="""",J24=0,L24=""0:""),"""",IFNA(INDEX(FILTER(Blocks!$A$2:$A1006, Blocks!$E$2:$E1006>=D24, Blocks!$F$2:$F1006>=E24, Blocks!$D$2:$D1006>=J24),1),""X""))"),"A") -> A | J24: =left(K24,find(":",K24)-1)+left(L24,find(":",L24)-1)+left(M24,find(":",M24)-1)+left(N24,find(":",N24)-1)+left(O24,find(":",O24)-1)+left(P24,find(":",P24)-1)+left(Q24,find(":",Q24)-1)+left(R24,find(":",R24)-1) -> 22 | K24: 1:VDD | L24: 1:VSS | M24: 0: | N24: 0: | O24: 9:cmd_valid cmd_data[0] cmd_data[1] cmd_data[2] cmd_data[3] cmd_data[4] cmd_data[5] cmd_data[6] cmd_data[7] | P24: 2:clk rst_n | Q24: 9:rsp_data[0] rsp_data[1] rsp_data[2] rsp_data[3] rsp_data[4] rsp_data[5] rsp_data[6] rsp_data[7] rsp_valid | R24: 0: | S24: 0:
A25: A56 | B25: dla_engine_chip | C25: dla_engine_chip.gds | D25: 1675 | E25: 1110 | F25: =IFERROR(and(vlookup(D25,Blocks!E$2:E$12,1,0),vlookup(E25,Blocks!F$2:F$12,1,0)),false) -> TRUE | G25: =ifna(if(vlookup(A25,Export!B:B,1,0)<>"","OK"),"") -> OK | H25: =vlookup(A25,Status!A:C,3,0) | I25: =IFERROR(__xludf.DUMMYFUNCTION("IF(or(D25="""",J25=0,L25=""0:""),"""",IFNA(INDEX(FILTER(Blocks!$A$2:$A1006, Blocks!$E$2:$E1006>=D25, Blocks!$F$2:$F1006>=E25, Blocks!$D$2:$D1006>=J25),1),""X""))"),"ACV") -> ACV | J25: =left(K25,find(":",K25)-1)+left(L25,find(":",L25)-1)+left(M25,find(":",M25)-1)+left(N25,find(":",N25)-1)+left(O25,find(":",O25)-1)+left(P25,find(":",P25)-1)+left(Q25,find(":",Q25)-1)+left(R25,find(":",R25)-1) -> 11 | K25: 1:DVDD | L25: 1:DVSS | M25: 0: | N25: 0: | O25: 1:rst_n | P25: 1:clk | Q25: 0: | R25: 7:SCLK MOSI CS_N MISO busy done wb_done | S25: 0:
A26: A63 | B26: spi_opentarget_i3c_top | C26: spi_opentarget_i3c_top.gds | D26: 450 | E26: 450 | F26: =IFERROR(and(vlookup(D26,Blocks!E$2:E$12,1,0),vlookup(E26,Blocks!F$2:F$12,1,0)),false) -> FALSE | G26: =ifna(if(vlookup(A26,Export!B:B,1,0)<>"","OK"),"") -> OK | H26: =vlookup(A26,Status!A:C,3,0) | I26: =IFERROR(__xludf.DUMMYFUNCTION("IF(or(D26="""",J26=0,L26=""0:""),"""",IFNA(INDEX(FILTER(Blocks!$A$2:$A1006, Blocks!$E$2:$E1006>=D26, Blocks!$F$2:$F1006>=E26, Blocks!$D$2:$D1006>=J26),1),""X""))"),"BV") -> BV | J26: =left(K26,find(":",K26)-1)+left(L26,find(":",L26)-1)+left(M26,find(":",M26)-1)+left(N26,find(":",N26)-1)+left(O26,find(":",O26)-1)+left(P26,find(":",P26)-1)+left(Q26,find(":",Q26)-1)+left(R26,find(":",R26)-1) -> 12 | K26: 1:VDD | L26: 1:VSS | M26: 0: | N26: 0: | O26: 7:rst_ni clk_i host_clk_i spi_sclk_i spi_cs_ni spi_mosi_i scl_pad_i | P26: 0: | Q26: 3:spi_miso_o *sda_pad irq_o | R26: 0: | S26: 2:sda_pad_i sda_pad_o | T26: missing sda_pad_IN|sda_pad_OUT
A27: A64 | B27: fdda_top | C27: fdda_top.gds | D27: 278.44 | E27: 160.66 | F27: =IFERROR(and(vlookup(D27,Blocks!E$2:E$12,1,0),vlookup(E27,Blocks!F$2:F$12,1,0)),false) -> FALSE | G27: =ifna(if(vlookup(A27,Export!B:B,1,0)<>"","OK"),"") -> OK | H27: =vlookup(A27,Status!A:C,3,0) | I27: =IFERROR(__xludf.DUMMYFUNCTION("IF(or(D27="""",J27=0,L27=""0:""),"""",IFNA(INDEX(FILTER(Blocks!$A$2:$A1006, Blocks!$E$2:$E1006>=D27, Blocks!$F$2:$F1006>=E27, Blocks!$D$2:$D1006>=J27),1),""X""))"),"D") -> D | J27: =left(K27,find(":",K27)-1)+left(L27,find(":",L27)-1)+left(M27,find(":",M27)-1)+left(N27,find(":",N27)-1)+left(O27,find(":",O27)-1)+left(P27,find(":",P27)-1)+left(Q27,find(":",Q27)-1)+left(R27,find(":",R27)-1) -> 8 | K27: 1:VDD_3v3 | L27: 1:GND | M27: 0: | N27: 6:Vnn Vnp Vpp Vpn Von Vop | O27: 0: | P27: 0: | Q27: 0: | R27: 0: | S27: 16:1a 1b 2a 2b 3a 3b 5 7 8 Bias_aux CM_neg CM_pos Gbias_20u_n Gbias_20u_p Vcm Vcmfb
A28: A66 | B28: PLL_top | C28: PLL_top.gds | D28: 500 | E28: 500 | F28: =IFERROR(and(vlookup(D28,Blocks!E$2:E$12,1,0),vlookup(E28,Blocks!F$2:F$12,1,0)),false) -> FALSE | G28: =ifna(if(vlookup(A28,Export!B:B,1,0)<>"","OK"),"") -> OK | H28: =vlookup(A28,Status!A:C,3,0) | I28: =IFERROR(__xludf.DUMMYFUNCTION("IF(or(D28="""",J28=0,L28=""0:""),"""",IFNA(INDEX(FILTER(Blocks!$A$2:$A1006, Blocks!$E$2:$E1006>=D28, Blocks!$F$2:$F1006>=E28, Blocks!$D$2:$D1006>=J28),1),""X""))"),"D") -> D | J28: =left(K28,find(":",K28)-1)+left(L28,find(":",L28)-1)+left(M28,find(":",M28)-1)+left(N28,find(":",N28)-1)+left(O28,find(":",O28)-1)+left(P28,find(":",P28)-1)+left(Q28,find(":",Q28)-1)+left(R28,find(":",R28)-1) -> 10 | K28: 1:*vdd | L28: 1:*vss | M28: 0: | N28: 1:*Vctrl | O28: 0: | P28: 3:*Fref *SDA *SCL | Q28: 4:*CK0 *CK90 *CK180 *CK270 | R28: 0: | S28: 0: | T28: missing CK0_IN|CK0_OUT; missing CK90_IN|CK90_OUT; missing CK180_IN|CK180_OUT; missing CK270_IN|CK270_OUT; missing Fref; missing Vctrl; missing SDA; missing SCL; missing vdd; missing vss
A29: A68 | B29: ascon_top | C29: ascon_top.gds | D29: 1000 | E29: 1000 | F29: =IFERROR(and(vlookup(D29,Blocks!E$2:E$12,1,0),vlookup(E29,Blocks!F$2:F$12,1,0)),false) -> FALSE | G29: =ifna(if(vlookup(A29,Export!B:B,1,0)<>"","OK"),"") -> OK | H29: =vlookup(A29,Status!A:C,3,0) | I29: =IFERROR(__xludf.DUMMYFUNCTION("IF(or(D29="""",J29=0,L29=""0:""),"""",IFNA(INDEX(FILTER(Blocks!$A$2:$A1006, Blocks!$E$2:$E1006>=D29, Blocks!$F$2:$F1006>=E29, Blocks!$D$2:$D1006>=J29),1),""X""))"),"A") -> A | J29: =left(K29,find(":",K29)-1)+left(L29,find(":",L29)-1)+left(M29,find(":",M29)-1)+left(N29,find(":",N29)-1)+left(O29,find(":",O29)-1)+left(P29,find(":",P29)-1)+left(Q29,find(":",Q29)-1)+left(R29,find(":",R29)-1) -> 8 | K29: 1:VDD | L29: 1:VSS | M29: 0: | N29: 0: | O29: 3:rst cs_n mosi | P29: 2:clk sclk | Q29: 1:miso | R29: 0:
A30: A71 | B30: lambda_kv_coproc | C30: lambda_kv_coproc.gds | D30: 502.89 | E30: 520.81 | F30: =IFERROR(and(vlookup(D30,Blocks!E$2:E$12,1,0),vlookup(E30,Blocks!F$2:F$12,1,0)),false) -> FALSE | G30: =ifna(if(vlookup(A30,Export!B:B,1,0)<>"","OK"),"") | H30: =vlookup(A30,Status!A:C,3,0) | I30: =IFERROR(__xludf.DUMMYFUNCTION("IF(or(D30="""",J30=0,L30=""0:""),"""",IFNA(INDEX(FILTER(Blocks!$A$2:$A1006, Blocks!$E$2:$E1006>=D30, Blocks!$F$2:$F1006>=E30, Blocks!$D$2:$D1006>=J30),1),""X""))"),"BV") -> BV | J30: =left(K30,find(":",K30)-1)+left(L30,find(":",L30)-1)+left(M30,find(":",M30)-1)+left(N30,find(":",N30)-1)+left(O30,find(":",O30)-1)+left(P30,find(":",P30)-1)+left(Q30,find(":",Q30)-1)+left(R30,find(":",R30)-1) -> 12 | K30: 1:VDD | L30: 1:VSS | M30: 0: | N30: 0: | O30: 4:rst_n spi_sclk spi_cs_n spi_mosi | P30: 1:clk | Q30: 5:spi_miso obs0 obs1 obs2 obs3 | R30: 0: | S30: 0:
A31: B02 | B31: ABC123_SDC | C31: ABC123_SDC.gds | F31: =IFERROR(and(vlookup(D31,Blocks!E$2:E$12,1,0),vlookup(E31,Blocks!F$2:F$12,1,0)),false) -> FALSE | G31: =ifna(if(vlookup(A31,Export!B:B,1,0)<>"","OK"),"") | H31: =vlookup(A31,Status!A:C,3,0) | I31: =IFERROR(__xludf.DUMMYFUNCTION("IF(or(D31="""",J31=0,L31=""0:""),"""",IFNA(INDEX(FILTER(Blocks!$A$2:$A1006, Blocks!$E$2:$E1006>=D31, Blocks!$F$2:$F1006>=E31, Blocks!$D$2:$D1006>=J31),1),""X""))"),"") | J31: =left(K31,find(":",K31)-1)+left(L31,find(":",L31)-1)+left(M31,find(":",M31)-1)+left(N31,find(":",N31)-1)+left(O31,find(":",O31)-1)+left(P31,find(":",P31)-1)+left(Q31,find(":",Q31)-1)+left(R31,find(":",R31)-1) -> 15 | K31: 1:VDD_1 | L31: 1:VSS_1 | M31: 2:CSENS CREF | N31: 1:VCTRL | O31: 7:CAPBANK[0] CAPBANK[1] CAPBANK[2] DFF_IN_SEL DFF_IN1 DFF_IN2 CHOP | P31: 0: | Q31: 3:CCOSENS_OUT CCOREF_OUT DOUT | R31: 0: | S31: 0: | T31: TOP_LAYOUT cell 'ABC123_SDC' not found in GDS
A32: B04 | B32: B04_TOP | C32: B04_TOP.gds | D32: 1110 | E32: 1110 | F32: =IFERROR(and(vlookup(D32,Blocks!E$2:E$12,1,0),vlookup(E32,Blocks!F$2:F$12,1,0)),false) -> TRUE | G32: =ifna(if(vlookup(A32,Export!B:B,1,0)<>"","OK"),"") -> OK | H32: =vlookup(A32,Status!A:C,3,0) | I32: =IFERROR(__xludf.DUMMYFUNCTION("IF(or(D32="""",J32=0,L32=""0:""),"""",IFNA(INDEX(FILTER(Blocks!$A$2:$A1006, Blocks!$E$2:$E1006>=D32, Blocks!$F$2:$F1006>=E32, Blocks!$D$2:$D1006>=J32),1),""X""))"),"A") -> A | J32: =left(K32,find(":",K32)-1)+left(L32,find(":",L32)-1)+left(M32,find(":",M32)-1)+left(N32,find(":",N32)-1)+left(O32,find(":",O32)-1)+left(P32,find(":",P32)-1)+left(Q32,find(":",Q32)-1)+left(R32,find(":",R32)-1) -> 10 | K32: 1:VDD | L32: 1:GND | M32: 0: | N32: 4:Vin Vbpf Venvelope Vthreshold | O32: 1:en | P32: 1:scl | Q32: 2:Vtrigger sda | R32: 0: | S32: 0:
A33: B08 | B33: TOP | C33: TOP.gds | D33: 251.93 | E33: 279.4 | F33: =IFERROR(and(vlookup(D33,Blocks!E$2:E$12,1,0),vlookup(E33,Blocks!F$2:F$12,1,0)),false) -> FALSE | G33: =ifna(if(vlookup(A33,Export!B:B,1,0)<>"","OK"),"") | H33: =vlookup(A33,Status!A:C,3,0) | I33: =IFERROR(__xludf.DUMMYFUNCTION("IF(or(D33="""",J33=0,L33=""0:""),"""",IFNA(INDEX(FILTER(Blocks!$A$2:$A1006, Blocks!$E$2:$E1006>=D33, Blocks!$F$2:$F1006>=E33, Blocks!$D$2:$D1006>=J33),1),""X""))"),"") | J33: =left(K33,find(":",K33)-1)+left(L33,find(":",L33)-1)+left(M33,find(":",M33)-1)+left(N33,find(":",N33)-1)+left(O33,find(":",O33)-1)+left(P33,find(":",P33)-1)+left(Q33,find(":",Q33)-1)+left(R33,find(":",R33)-1) -> 0 | K33: 0: | L33: 0: | M33: 0: | N33: 0: | O33: 0: | P33: 0: | Q33: 0: | R33: 0: | S33: 0: | T33: pin entry 5 ('CLK') has unsupported pad type 'digital'
A34: B11 | B34: B11_CuriousIC_DryRun_Top | C34: B11_CuriousIC_DryRun_Top_26Aug.gds | D34: 600 | E34: 600 | F34: =IFERROR(and(vlookup(D34,Blocks!E$2:E$12,1,0),vlookup(E34,Blocks!F$2:F$12,1,0)),false) -> FALSE | G34: =ifna(if(vlookup(A34,Export!B:B,1,0)<>"","OK"),"") -> OK | H34: =vlookup(A34,Status!A:C,3,0) | I34: =IFERROR(__xludf.DUMMYFUNCTION("IF(or(D34="""",J34=0,L34=""0:""),"""",IFNA(INDEX(FILTER(Blocks!$A$2:$A1006, Blocks!$E$2:$E1006>=D34, Blocks!$F$2:$F1006>=E34, Blocks!$D$2:$D1006>=J34),1),""X""))"),"A") -> A | J34: =left(K34,find(":",K34)-1)+left(L34,find(":",L34)-1)+left(M34,find(":",M34)-1)+left(N34,find(":",N34)-1)+left(O34,find(":",O34)-1)+left(P34,find(":",P34)-1)+left(Q34,find(":",Q34)-1)+left(R34,find(":",R34)-1) -> 22 | K34: 2:*B11_BMS_DVDD *B11_BMS_AVDD | L34: 2:*B11_BMS_DVSS *B11_BMS_AVSS | M34: 6:*B11_BMS_VINN_CH1 *B11_BMS_VINP_CH1 *B11_BMS_VREFP *B11_BMS_IBIAS_5u *B11_BMS_VCM *B11_BMS_ATB_IA_ADC | N34: 0: | O34: 10:*B11_BMS_CLKIN *B11_BMS_CLK_FCHOP *B11_BMS_EN_EIS *B11_BMS_EIS_RESET *B11_BMS_CH_SEL *B11_BMS_ATB_SEL_0 *B11_BMS_ATB_SEL_1 *B11_BMS_D_EIS *B11_BMS_CLK_EIS *B11_BMS_DOUT | P34: 0: | Q34: 2:*B11_BMS_VINN_CH2 *B11_BMS_VINP_CH2 | R34: 0: | S34: 0: | T34: missing B11_BMS_DVSS; missing B11_BMS_CLKIN; missing B11_BMS_CLK_FCHOP; missing B11_BMS_DVDD; missing B11_BMS_VINN_CH1; missing B11_BMS_VINP_CH1; missing B11_BMS_VREFP; missing B11_BMS_IBIAS_5u; missing B11_BMS_VCM; missing B11_BMS_VINN_CH2_IN|B11_BMS_VINN_CH2_OUT; missing B11_BMS_VINP_CH2_IN|B11_BMS_VINP_CH2_OUT; missing B11_BMS_EN_EIS; missing B11_BMS_EIS_RESET; missing B11_BMS_AVSS; missing B11_BMS_AVDD; missing B11_BMS_CH_SEL; missing B11_BMS_ATB_SEL_0; missing B11_BMS_ATB_SEL_1; missing B11_BMS_D_EIS; missing B11_BMS_CLK_EIS; missing B11_BMS_ATB_IA_ADC; missing B11_BMS_DOUT
A35: B12 | B35: perceptron | C35: perceptron.gds | D35: 135.81 | E35: 138.87 | F35: =IFERROR(and(vlookup(D35,Blocks!E$2:E$12,1,0),vlookup(E35,Blocks!F$2:F$12,1,0)),false) -> FALSE | G35: =ifna(if(vlookup(A35,Export!B:B,1,0)<>"","OK"),"") -> OK | H35: =vlookup(A35,Status!A:C,3,0) | I35: =IFERROR(__xludf.DUMMYFUNCTION("IF(or(D35="""",J35=0,L35=""0:""),"""",IFNA(INDEX(FILTER(Blocks!$A$2:$A1006, Blocks!$E$2:$E1006>=D35, Blocks!$F$2:$F1006>=E35, Blocks!$D$2:$D1006>=J35),1),""X""))"),"D") -> D | J35: =left(K35,find(":",K35)-1)+left(L35,find(":",L35)-1)+left(M35,find(":",M35)-1)+left(N35,find(":",N35)-1)+left(O35,find(":",O35)-1)+left(P35,find(":",P35)-1)+left(Q35,find(":",Q35)-1)+left(R35,find(":",R35)-1) -> 9 | K35: 1:VDD | L35: 1:VSS | M35: 0: | N35: 7:V_w2 I_x2 V_b I_x1 V_w1 V_shift V_out_perceptron | O35: 0: | P35: 0: | Q35: 0: | R35: 0: | S35: 0:
A36: B14 | B36: B14_A | C36: B14_A.gds | D36: 1110 | E36: 1110 | F36: =IFERROR(and(vlookup(D36,Blocks!E$2:E$12,1,0),vlookup(E36,Blocks!F$2:F$12,1,0)),false) -> TRUE | G36: =ifna(if(vlookup(A36,Export!B:B,1,0)<>"","OK"),"") -> OK | H36: =vlookup(A36,Status!A:C,3,0) | I36: =IFERROR(__xludf.DUMMYFUNCTION("IF(or(D36="""",J36=0,L36=""0:""),"""",IFNA(INDEX(FILTER(Blocks!$A$2:$A1006, Blocks!$E$2:$E1006>=D36, Blocks!$F$2:$F1006>=E36, Blocks!$D$2:$D1006>=J36),1),""X""))"),"A") -> A | J36: =left(K36,find(":",K36)-1)+left(L36,find(":",L36)-1)+left(M36,find(":",M36)-1)+left(N36,find(":",N36)-1)+left(O36,find(":",O36)-1)+left(P36,find(":",P36)-1)+left(Q36,find(":",Q36)-1)+left(R36,find(":",R36)-1) -> 18 | K36: 1:VDD | L36: 1:VSS | M36: 5:VREF_P VREF_N RE TIA_R CE | N36: 11:B6 B4 B2 B0 B1 B3 B5 B7 VbiasN AGND WE | O36: 0: | P36: 0: | Q36: 0: | R36: 0: | S36: 0:
A37: B18 | B37: B18_Probton | C37: B18_Probton.gds | D37: 1110 | E37: 1110 | F37: =IFERROR(and(vlookup(D37,Blocks!E$2:E$12,1,0),vlookup(E37,Blocks!F$2:F$12,1,0)),false) -> TRUE | G37: =ifna(if(vlookup(A37,Export!B:B,1,0)<>"","OK"),"") -> OK | H37: =vlookup(A37,Status!A:C,3,0) | I37: =IFERROR(__xludf.DUMMYFUNCTION("IF(or(D37="""",J37=0,L37=""0:""),"""",IFNA(INDEX(FILTER(Blocks!$A$2:$A1006, Blocks!$E$2:$E1006>=D37, Blocks!$F$2:$F1006>=E37, Blocks!$D$2:$D1006>=J37),1),""X""))"),"A") -> A | J37: =left(K37,find(":",K37)-1)+left(L37,find(":",L37)-1)+left(M37,find(":",M37)-1)+left(N37,find(":",N37)-1)+left(O37,find(":",O37)-1)+left(P37,find(":",P37)-1)+left(Q37,find(":",Q37)-1)+left(R37,find(":",R37)-1) -> 19 | K37: 1:VDD | L37: 1:VSS | M37: 0: | N37: 0: | O37: 4:spi_sclk clk comp_x comp_y | P37: 3:rst_n spi_cs_n spi_mosi | Q37: 10:spi_miso move_en_x dir_x ref_wave_x mems_drv_x mems_drv_y ref_wave_y dir_y move_en_y read_en | R37: 0: | S37: 0:
A38: B23 | B38: B23_TEMPX_DryRun_Top | C38: B23_TempX.gds | D38: 600 | E38: 600 | F38: =IFERROR(and(vlookup(D38,Blocks!E$2:E$12,1,0),vlookup(E38,Blocks!F$2:F$12,1,0)),false) -> FALSE | G38: =ifna(if(vlookup(A38,Export!B:B,1,0)<>"","OK"),"") | H38: =vlookup(A38,Status!A:C,3,0) | I38: =IFERROR(__xludf.DUMMYFUNCTION("IF(or(D38="""",J38=0,L38=""0:""),"""",IFNA(INDEX(FILTER(Blocks!$A$2:$A1006, Blocks!$E$2:$E1006>=D38, Blocks!$F$2:$F1006>=E38, Blocks!$D$2:$D1006>=J38),1),""X""))"),"A") -> A | J38: =left(K38,find(":",K38)-1)+left(L38,find(":",L38)-1)+left(M38,find(":",M38)-1)+left(N38,find(":",N38)-1)+left(O38,find(":",O38)-1)+left(P38,find(":",P38)-1)+left(Q38,find(":",Q38)-1)+left(R38,find(":",R38)-1) -> 14 | K38: 2:*AVDD *DVDD | L38: 2:*AGND *DGND | M38: 0: | N38: 0: | O38: 6:*CLK *RESET *ENABLE *TEST_SEL_2 *TEST_SEL_1 *TEST_SEL_0 | P38: 0: | Q38: 4:*DATA_OUT *DATA_VALID *TEST_ANALOG *TEST_OUT | R38: 0: | S38: 0: | T38: missing AGND; missing AVDD; missing DVDD; missing DGND; missing CLK; missing RESET; missing ENABLE; missing TEST_SEL_2; missing TEST_SEL_1; missing TEST_SEL_0; missing DATA_OUT_IN|DATA_OUT_OUT; missing DATA_VALID_IN|DATA_VALID_OUT; missing TEST_ANALOG_IN|TEST_ANALOG_OUT; missing TEST_OUT_IN|TEST_OUT_OUT
A39: B24 | B39: B24_topcell | C39: B24_topcell.gds | F39: =IFERROR(and(vlookup(D39,Blocks!E$2:E$12,1,0),vlookup(E39,Blocks!F$2:F$12,1,0)),false) -> FALSE | G39: =ifna(if(vlookup(A39,Export!B:B,1,0)<>"","OK"),"") -> OK | H39: =vlookup(A39,Status!A:C,3,0) | I39: =IFERROR(__xludf.DUMMYFUNCTION("IF(or(D39="""",J39=0,L39=""0:""),"""",IFNA(INDEX(FILTER(Blocks!$A$2:$A1006, Blocks!$E$2:$E1006>=D39, Blocks!$F$2:$F1006>=E39, Blocks!$D$2:$D1006>=J39),1),""X""))"),"") | J39: =left(K39,find(":",K39)-1)+left(L39,find(":",L39)-1)+left(M39,find(":",M39)-1)+left(N39,find(":",N39)-1)+left(O39,find(":",O39)-1)+left(P39,find(":",P39)-1)+left(Q39,find(":",Q39)-1)+left(R39,find(":",R39)-1) -> 18 | K39: 2:VSET VDD | L39: 1:GND | M39: 0: | N39: 15:Ibias LED_K Comparator_out HPF_outp HPF_outn HPF_inp HPF_inn Vb1 Vb2 Vb3 Vb4 LPF_outp LPF_outn LPF_inp LPF_inn | O39: 0: | P39: 0: | Q39: 0: | R39: 0: | S39: 0: | T39: group 2 missing ground: VDD HPF_outp HPF_outn HPF_inp HPF_inn Vb1 Vb2 Vb3 Vb4 LPF_outp LPF_outn LPF_inp LPF_inn; TOP_LAYOUT cell 'B24_topcell' not found in GDS
A40: B26 | B40: GRADIENT_NAV2 | C40: GRADIENT_NAV2_filled.gds | D40: 418.24 | E40: 442.19 | F40: =IFERROR(and(vlookup(D40,Blocks!E$2:E$12,1,0),vlookup(E40,Blocks!F$2:F$12,1,0)),false) -> FALSE | G40: =ifna(if(vlookup(A40,Export!B:B,1,0)<>"","OK"),"") -> OK | H40: =vlookup(A40,Status!A:C,3,0) | I40: =IFERROR(__xludf.DUMMYFUNCTION("IF(or(D40="""",J40=0,L40=""0:""),"""",IFNA(INDEX(FILTER(Blocks!$A$2:$A1006, Blocks!$E$2:$E1006>=D40, Blocks!$F$2:$F1006>=E40, Blocks!$D$2:$D1006>=J40),1),""X""))"),"A") -> A | J40: =left(K40,find(":",K40)-1)+left(L40,find(":",L40)-1)+left(M40,find(":",M40)-1)+left(N40,find(":",N40)-1)+left(O40,find(":",O40)-1)+left(P40,find(":",P40)-1)+left(Q40,find(":",Q40)-1)+left(R40,find(":",R40)-1) -> 19 | K40: 1:VDD | L40: 1:VSS | M40: 0: | N40: 11:S4P S4N Z Y X S1N S1P S3P S3N S2N S2P | O40: 0: | P40: 0: | Q40: 6:ZN ZP YN YP XN XP | R40: 0: | S40: 0:
...

Sheet Export
E1: is it EAR99?
A2: A02 AI_Byte | B2: =left(SUBSTITUTE(A2,"[",""), 3) -> A02 | C2: =right(A2,3) -> yte | D2: =iferror(mid(A2,find("(",A2)+1,3),"")
A3: A06 BUETCHIP | B3: =left(SUBSTITUTE(A3,"[",""), 3) -> A06 | C3: =right(A3,3) -> HIP | D3: =iferror(mid(A3,find("(",A3)+1,3),"")
A4: A64 UFJF On Chip | B4: =left(SUBSTITUTE(A4,"[",""), 3) -> A64 | C4: =right(A4,3) -> hip | D4: =iferror(mid(A4,find("(",A4)+1,3),"")
A5: A07 Blueprints | B5: =left(SUBSTITUTE(A5,"[",""), 3) -> A07 | C5: =right(A5,3) -> nts | D5: =iferror(mid(A5,find("(",A5)+1,3),"")
A6: B18 Probton | B6: =left(SUBSTITUTE(A6,"[",""), 3) -> B18 | C6: =right(A6,3) -> ton | D6: =iferror(mid(A6,find("(",A6)+1,3),"")
A7: C05 MRTMOS | B7: =left(SUBSTITUTE(A7,"[",""), 3) -> C05 | C7: =right(A7,3) -> MOS | D7: =iferror(mid(A7,find("(",A7)+1,3),"")
